<?xml version="1.0" ?>
<sdf version="1.8">
    <world name="car_world">
        <physics name="1ms" type="ignored">
            <max_step_size>0.001</max_step_size>
            <real_time_factor>1.0</real_time_factor>
        </physics>
        <plugin
            filename="libignition-gazebo-physics-system.so"
            name="ignition::gazebo::systems::Physics">
        </plugin>
        <plugin
            filename="libignition-gazebo-user-commands-system.so"
            name="ignition::gazebo::systems::UserCommands">
        </plugin>
        <plugin
            filename="libignition-gazebo-scene-broadcaster-system.so"
            name="ignition::gazebo::systems::SceneBroadcaster">
        </plugin>

        <light type="directional" name="sun">
            <cast_shadows>true</cast_shadows>
            <pose>0 0 10 0 0 0</pose>
            <diffuse>0.8 0.8 0.8 1</diffuse>
            <specular>0.2 0.2 0.2 1</specular>
            <attenuation>
                <range>1000</range>
                <constant>0.9</constant>
                <linear>0.01</linear>
                <quadratic>0.001</quadratic>
            </attenuation>
            <direction>-0.5 0.1 -0.9</direction>
        </light>

        <model name="ground_plane">
            <static>true</static>
            <link name="link">
                <collision name="collision">
                <geometry>
                    <plane>
                    <normal>0 0 1</normal>
                    </plane>
                </geometry>
                </collision>
                <visual name="visual">
                <geometry>
                    <plane>
                    <normal>0 0 1</normal>
                    <size>100 100</size>
                    </plane>
                </geometry>
                <material>
                    <ambient>0.8 0.8 0.8 1</ambient>
                    <diffuse>0.8 0.8 0.8 1</diffuse>
                    <specular>0.8 0.8 0.8 1</specular>
                </material>
                </visual>
            </link>
        </model>
        

        <model name='astro' canonical_link='chassis'>
            <pose relative_to='world'>0 0 0 0 0 0</pose>
            

            <link name='chassis'>
                <pose relative_to='__model__'>0 0 0.0506 0 0 0</pose>

                <inertial> 
                    <mass>4.03</mass>
                    <inertia>
                        <ixx>0.04056665167</ixx>
                        <ixy>0</ixy>
                        <ixz>0</ixz>
                        <iyy>0.03789879167</iyy>
                        <iyz>0</iyz>
                        <izz>0.07361265167</izz>
                    </inertia>
                </inertial>

                <visual name='visual'>
                    <geometry>
                        <mesh>
                            <uri>model://ASTRO_Chassis.stl</uri>
                            <scale>0.001 0.001 0.001</scale>
                        </mesh>
                    </geometry>
                
                    <material>
                        <ambient>0.027450980392156862 0.050980392156862744 0.050980392156862744 1</ambient>
                        <diffuse>0.027450980392156862 0.050980392156862744 0.050980392156862744 1</diffuse>
                        <specular>0.027450980392156862 0.050980392156862744 0.050980392156862744 1</specular>
                    </material>
                </visual>

                <collision name='collision'>
                    <geometry>
                        <mesh>
                            <uri>model://ASTRO_Chassis.stl</uri>
                            <scale>0.001 0.001 0.001</scale>
                        </mesh>
                    </geometry>
                </collision>
            </link>

            <link name='left_wheel'>
                <pose relative_to="chassis">0 0.153 0 -1.5707 0 0</pose>
                <inertial>
                    <mass>0.07</mass>
                    <inertia>
                        <ixx>0.0000241733</ixx>
                        <ixy>0</ixy>
                        <ixz>0</ixz>
                        <iyy>0.0000241733</iyy>
                        <iyz>0</iyz>
                        <izz>0.00004536</izz>
                    </inertia>
                </inertial>
            
                <visual name='visual'>
                    <geometry>
                        <cylinder>
                            <radius>0.0360</radius>
                            <length>0.0160</length>
                        </cylinder>
                    </geometry>
                    <material>
                        <ambient>0.5725490196078431 0.5843137254901961 0.5686274509803921 1</ambient>
                        <diffuse>0.5725490196078431 0.5843137254901961 0.5686274509803921 1</diffuse>
                        <specular>0.5725490196078431 0.5843137254901961 0.5686274509803921 1</specular>
                    </material>
                </visual>
                <collision name='collision'>
                    <geometry>
                        <cylinder>
                            <radius>0.0360</radius>
                            <length>0.0160</length>
                        </cylinder>
                    </geometry>
                </collision>
            </link>


            <joint name='left_wheel_joint' type='revolute'>
                <pose relative_to='left_wheel'/>
                <parent>chassis</parent>
                <child>left_wheel</child>
                <axis>
                    <xyz expressed_in='__model__'>0 1 0</xyz> 
                    <limit>
                        <lower>-1.79769e+308</lower>    
                        <upper>1.79769e+308</upper>     
                    </limit>
                </axis>
            </joint>
        

            <link name='right_wheel'>
                <pose relative_to="chassis">0 -0.153 0 -1.5707 0 0</pose>
                <inertial>
                    <mass>0.07</mass>
                    <inertia>
                        <ixx>0.0000241733</ixx>
                        <ixy>0</ixy>
                        <ixz>0</ixz>
                        <iyy>0.0000241733</iyy>
                        <iyz>0</iyz>
                        <izz>0.00004536</izz>
                    </inertia>
                </inertial>
            
                <visual name='visual'>
                    <geometry>
                        <cylinder>
                            <radius>0.0360</radius>
                            <length>0.0160</length>
                        </cylinder>
                    </geometry>
                    <material>
                        <ambient>0.5725490196078431 0.5843137254901961 0.5686274509803921 1</ambient>
                        <diffuse>0.5725490196078431 0.5843137254901961 0.5686274509803921 1</diffuse>
                        <specular>0.5725490196078431 0.5843137254901961 0.5686274509803921 1</specular>
                    </material>
                </visual>
                <collision name='collision'>
                    <geometry>
                        <cylinder>
                            <radius>0.0360</radius>
                            <length>0.0160</length>
                        </cylinder>
                    </geometry>
                </collision>
            </link>


            <joint name='right_wheel_joint' type='revolute'>
                <pose relative_to='right_wheel'/>
                <parent>chassis</parent>
                <child>right_wheel</child>
                <axis>
                    <xyz expressed_in='__model__'>0 1 0</xyz>
                    <limit>
                        <lower>-1.79769e+308</lower>    
                        <upper>1.79769e+308</upper>     
                    </limit>
                </axis>
            </joint>


            <frame name="fl_caster_frame" attached_to='chassis'>
                <pose>0.096 0.0965 -0.0214 0 0 0</pose>
            </frame>

            <link name='fl_caster_wheel'>
                <pose relative_to='fl_caster_frame'/>
                <inertial>
                    <mass>0.063</mass>
                    <inertia>
                        <ixx>0.000005371632</ixx>
                        <ixy>0</ixy>
                        <ixz>0</ixz>
                        <iyy>0.000005371632</iyy>
                        <iyz>0</iyz>
                        <izz>0.000005371632</izz>
                    </inertia>
                </inertial>
                <visual name='visual'>
                    <geometry>
                        <sphere>
                            <radius>0.0146</radius>
                        </sphere>
                    </geometry>
                    <material>
                        <ambient>1.0 1.0 1.0 1</ambient>
                        <diffuse>1.0 1.0 1.0 1</diffuse>
                        <specular>1.0 1 1.0 1</specular>
                    </material>
                </visual>
                <collision name='collision'>
                    <geometry>
                        <sphere>
                            <radius>0.0146</radius>
                        </sphere>
                    </geometry>
                </collision>
            </link>

            <joint name='fl_caster_joint' type='ball'>
                <parent>chassis</parent>
                <child>fl_caster_wheel</child>
            </joint>


            <frame name="fr_caster_frame" attached_to='chassis'>
                <pose>0.096 -0.0965 -0.0214 0 0 0</pose>
            </frame>

            <link name='fr_caster_wheel'>
                <pose relative_to='fr_caster_frame'/>
                <inertial>
                    <mass>0.063</mass>
                    <inertia>
                        <ixx>0.000005371632</ixx>
                        <ixy>0</ixy>
                        <ixz>0</ixz>
                        <iyy>0.000005371632</iyy>
                        <iyz>0</iyz>
                        <izz>0.000005371632</izz>
                    </inertia>
                </inertial>
                <visual name='visual'>
                    <geometry>
                        <sphere>
                            <radius>0.0146</radius>
                        </sphere>
                    </geometry>
                    <material>
                        <ambient>1.0 1 1.0 1</ambient>
                        <diffuse>1.0 1 1.0 1</diffuse>
                        <specular>1.0 1 1.0 1</specular>
                    </material>
                </visual>
                <collision name='collision'>
                    <geometry>
                        <sphere>
                            <radius>0.0146</radius>
                        </sphere>
                    </geometry>
                </collision>
            </link>

            <joint name='fr_caster_joint' type='ball'>
                <parent>chassis</parent>
                <child>fr_caster_wheel</child>
            </joint>

            
            <frame name="bl_caster_frame" attached_to='chassis'>
                <pose>-0.092 0.1265 -0.0214 0 0 0</pose>
            </frame>

            <link name='bl_caster_wheel'>
                <pose relative_to='bl_caster_frame'/>
                <inertial>
                    <mass>0.063</mass>
                    <inertia>
                        <ixx>0.000005371632</ixx>
                        <ixy>0</ixy>
                        <ixz>0</ixz>
                        <iyy>0.000005371632</iyy>
                        <iyz>0</iyz>
                        <izz>0.000005371632</izz>
                    </inertia>
                </inertial>
                <visual name='visual'>
                    <geometry>
                        <sphere>
                            <radius>0.0146</radius>
                        </sphere>
                    </geometry>
                    <material>
                        <ambient>1.0 1 1.0 1</ambient>
                        <diffuse>1.0 1 1.0 1</diffuse>
                        <specular>1.0 1 1.0 1</specular>
                    </material>
                </visual>
                <collision name='collision'>
                    <geometry>
                        <sphere>
                            <radius>0.0146</radius>
                        </sphere>
                    </geometry>
                </collision>
            </link>

            <joint name='bl_caster_joint' type='ball'>
                <parent>chassis</parent>
                <child>bl_caster_wheel</child>
            </joint>


            <frame name="br_caster_frame" attached_to='chassis'>
                <pose>-0.092 -0.1265 -0.0214 0 0 0</pose>
            </frame>

            <link name='br_caster_wheel'>
                <pose relative_to='br_caster_frame'/>
                <inertial>
                    <mass>0.063</mass>
                    <inertia>
                        <ixx>0.000005371632</ixx>
                        <ixy>0</ixy>
                        <ixz>0</ixz>
                        <iyy>0.000005371632</iyy>
                        <iyz>0</iyz>
                        <izz>0.000005371632</izz>
                    </inertia>
                </inertial>
                <visual name='visual'>
                    <geometry>
                        <sphere>
                            <radius>0.0146</radius>
                        </sphere>
                    </geometry>
                    <material>
                        <ambient>1.0 1 1.0 1</ambient>
                        <diffuse>1.0 1 1.0 1</diffuse>
                        <specular>1.0 1 1.0 1</specular>
                    </material>
                </visual>
                <collision name='collision'>
                    <geometry>
                        <sphere>
                            <radius>0.0146</radius>
                        </sphere>
                    </geometry>
                </collision>
            </link>

            <joint name='br_caster_joint' type='ball'>
                <parent>chassis</parent>
                <child>br_caster_wheel</child>
            </joint>


            <plugin
               filename="libignition-gazebo-diff-drive-system.so"
               name="ignition::gazebo::systems::DiffDrive">
               <left_joint>left_wheel_joint</left_joint>
               <right_joint>right_wheel_joint</right_joint>
               <wheel_separation>0.306</wheel_separation>
               <wheel_radius>0.0360</wheel_radius>
               <odom_publish_frequency>1</odom_publish_frequency>
               <topic>cmd_vel</topic>
            </plugin>


            <frame name="lidar_frame" attached_to='chassis'>
                <pose>0.038471 0 0.0838 0 0 0</pose>

                <visual></visual>
            </frame>


            <link name='lidar'>
                <pose relative_to='lidar_frame'/>
                <inertial>
                    <mass>0.26</mass>
                    <inertia>
                        <ixx>0.000001</ixx>
                        <ixy>0</ixy>
                        <ixz>0</ixz>
                        <iyy>0.000001</iyy>
                        <iyz>0</iyz>
                        <izz>0.000001</izz>
                    </inertia>
                </inertial>
                <visual name='visual'>
                    <geometry>
                        <mesh>
                            <uri>model://ASTRO_LidarAssembly.stl</uri>
                            <scale>0.001 0.001 0.001</scale>
                        </mesh>
                    </geometry>
                    <material>
                        <ambient>0.027450980392156862 0.050980392156862744 0.050980392156862744 1</ambient>
                        <diffuse>0.027450980392156862 0.050980392156862744 0.050980392156862744 1</diffuse>
                        <specular>0.027450980392156862 0.050980392156862744 0.050980392156862744 1</specular>
                    </material>
                </visual>
                <collision name='collision'>
                    <geometry>
                        <mesh>
                            <uri>model://ASTRO_LidarAssembly.stl</uri>
                            <scale>0.001 0.001 0.001</scale>
                        </mesh>
                    </geometry>
                </collision>

                <sensor name='gpu_lidar' type='gpu_lidar'>"
                    <pose relative_to='lidar_frame'>0 0 0 0 0 0</pose>
                    <topic>lidar</topic>
                    <update_rate>10</update_rate>
                    <ray>
                        <scan>
                            <horizontal>
                                <samples>360</samples>
                                <resolution>1</resolution>
                                <min_angle>-3.141592</min_angle>
                                <max_angle>3.141592</max_angle>
                            </horizontal>
                            <vertical>
                                <samples>1</samples>
                                <resolution>0.01</resolution>
                                <min_angle>0</min_angle>
                                <max_angle>0</max_angle>
                            </vertical>
                        </scan>
                        <range>
                            <min>0.3</min>
                            <max>12.0</max>
                            <resolution>0.01</resolution>
                        </range>
    
                        <noise>
                            <type>gaussian</type>
                            <mean>0.0</mean>
                            <stddev>0.005</stddev>
                        </noise>
                    </ray>
                    <always_on>1</always_on>
                    <visualize>true</visualize>
                </sensor>
            </link>

            <joint name='lidar_joint' type='fixed'>
                <parent>chassis</parent>
                <child>lidar</child>
            </joint>


            <plugin
               filename="libignition-gazebo-sensors-system.so"
               name="ignition::gazebo::systems::Sensors">
               <render_engine>ogre2</render_engine>
            
            </plugin>


            


            


            
     
            
        </model>
        
    </world>
</sdf>